Workbook

Sheet Overzicht 2026
A1: MAVEN PUBLISHING
A2: Bruto Marge Overzicht — Titels 2026
E4: 1E DRUK | J4: HERDRUK
A5: Titel | B5: Prijs incl BTW | C5: Oplage | E5: WS marge | F5: WS €/ex | G5: RT marge | H5: RT €/ex | J5: WS marge | K5: WS €/ex | L5: RT marge | M5: RT €/ex
A6: Co-intelligentie | B6: ='Co-intelligentie'!B4 -> 20 | C6: ='Co-intelligentie'!B7 -> 2000 | E6: ='Co-intelligentie'!C42 -> 0.142525 | F6: ='Co-intelligentie'!B42 -> 2.6151376 | G6: ='Co-intelligentie'!F42 -> 0.27370192 | H6: ='Co-intelligentie'!E42 -> 2.6114679 | J6: ='Co-intelligentie'!C66 -> 0.120725 | K6: ='Co-intelligentie'!B66 -> 2.2151376 | L6: ='Co-intelligentie'!F66 -> 0.23177885 | M6: ='Co-intelligentie'!E66 -> 2.2114679
A7: Rechts verpest onze seks | B7: ='Rechts verpest onze seks'!B4 -> 17.5 | C7: ='Rechts verpest onze seks'!B7 -> 2000 | E7: ='Rechts verpest onze seks'!C42 -> 0.32985332 | F7: ='Rechts verpest onze seks'!B42 -> 5.2958102 | G7: ='Rechts verpest onze seks'!F42 -> 0.39839238 | H7: ='Rechts verpest onze seks'!E42 -> 3.3260281 | J7: ='Rechts verpest onze seks'!C66 -> 0.32989786 | K7: ='Rechts verpest onze seks'!B66 -> 5.2965252 | L7: ='Rechts verpest onze seks'!F66 -> 0.39847802 | M7: ='Rechts verpest onze seks'!E66 -> 3.3267431
A8: 7 regels van vertrouwen | B8: ='7 regels van vertrouwen'!B4 -> 0 | C8: ='7 regels van vertrouwen'!B7 -> 0 | E8: ='7 regels van vertrouwen'!C42 -> 0 | F8: ='7 regels van vertrouwen'!B42 -> -4.7 | G8: ='7 regels van vertrouwen'!F42 -> 0 | H8: ='7 regels van vertrouwen'!E42 -> -1.1 | J8: ='7 regels van vertrouwen'!C66 -> 0 | K8: ='7 regels van vertrouwen'!B66 -> -4.7 | L8: ='7 regels van vertrouwen'!F66 -> 0 | M8: ='7 regels van vertrouwen'!E66 -> -1.1
A9: Nieuwe titel | B9: ='Nieuwe titel'!B4 -> 0 | C9: ='Nieuwe titel'!B7 -> 0 | E9: ='Nieuwe titel'!C42 -> 0 | F9: ='Nieuwe titel'!B42 -> -4.7 | G9: ='Nieuwe titel'!F42 -> 0 | H9: ='Nieuwe titel'!E42 -> -1.1 | J9: ='Nieuwe titel'!C66 -> 0 | K9: ='Nieuwe titel'!B66 -> -4.7 | L9: ='Nieuwe titel'!F66 -> 0 | M9: ='Nieuwe titel'!E66 -> -1.1

Sheet Co-intelligentie
A1: Co-intelligentie | H1: REDACTIE & PRODUCTIE
H2: Post | I2: Begroot | J2: Gerealiseerd
A3: BASISGEGEVENS | D3: DEALSTRUCTUUR | H3: Freelance redactie | I3: 0
A4: Verkoopprijs incl BTW | B4: 20 | D4: Royalty % | E4: 0 | H4: Correctie | I4: 0
A5: BTW % | B5: 0.09 | D5: Auteur winstdeling % | E5: 0.5 | H5: Persklaarmaken | I5: 0
A6: Boekhandelskorting % | B6: 0.48 | D6: Partner winstdeling % | E6: 0 | H6: Vormgeving & omslag | I6: 0
A7: Oplage 1e druk | B7: 2000 | H7: DTP | I7: 0
H8: E-book productie | I8: 0
A9: KOSTEN PER EXEMPLAAR | H9: Audiobook productie | I9: 0
A10: Drukkosten /ex (1e druk) | B10: 1.2 | H10: Drukkosten 1e druk | I10: =$B$10*$B$7 -> 2400
A11: Drukkosten /ex (herdruk) | B11: 2 | H11: Overige productie | I11: 0
A12: Fulfillment webshop /ex | B12: 4.7
A13: Distributie CB /ex | B13: 1.1 | H13: Subtotaal excl. drukkosten | I13: =SUM(I3:I9,I11) -> 0 | J13: =SUM(J3:J9,J11) -> 0
A14: Transactiekosten % (webshop) | B14: 0.01 | H14: Totaal incl. drukkosten | I14: =SUM(I3:I11) -> 2400 | J14: =SUM(J3:J11) -> 0
A15: Vertaler % | B15: 0 | H15: Per exemplaar (excl. druk) | I15: =IFERROR(I13/$B$7,0) -> 0 | J15: =IFERROR(J13/$B$7,0) -> 0
A16: Agent % | B16: 0.11
A17: Adspend webshop /ex | B17: 5 | H17: PR & MARKETING
A18: Overige kosten % | B18: 0 | H18: Post | I18: Begroot | J18: Gerealiseerd
H19: PR activiteiten | I19: 0
A20: 1E DRUK | H20: Marketingmateriaal | I20: 0
B21: WEBSHOP | E21: RETAIL | H21: Evenementen | I21: 0
B22: Bedrag | C22: % | E22: Bedrag | F22: % | H22: Campagnes / advertenties | I22: 0
A23: Verkoopprijs ex BTW | B23: =$B$4/(1+$B$5) -> 18.348624 | E23: =$B$4/(1+$B$5) -> 18.348624 | H23: Overige marketing | I23: 0
A24: Boekhandelskorting | B24: 0 | C24: 0 | E24: =E23*$B$6 -> 8.8073394 | F24: =$B$6 -> 0.48
A25: Netto omzet | B25: =B23 -> 18.348624 | E25: =E23-E24 -> 9.5412844 | H25: Totaal PR & Marketing | I25: =SUM(I19:I23) -> 0 | J25: =SUM(J19:J23) -> 0
A27: Drukkosten | B27: =$B$10 -> 1.2 | C27: =IFERROR(B27/B$25,0) -> 0.0654 | E27: =$B$10 -> 1.2 | F27: =IFERROR(E27/E$25,0) -> 0.12576923
A28: Redactie & productie /ex | B28: =IFERROR(I15/$B$7,0) -> 0 | C28: =IFERROR(B28/B$25,0) -> 0 | E28: =IFERROR(I15/$B$7,0) -> 0 | F28: =IFERROR(E28/E$25,0) -> 0 | H28: DRUKRUNS
A29: Fulfillment / B-Logic | B29: =$B$12 -> 4.7 | C29: =IFERROR(B29/B$25,0) -> 0.25615 | E29: 0 | F29: 0 | G29: alleen webshop | H29: Run | I29: Aantal | J29: Kosten /ex | K29: Totaal
A30: Distributie CB | B30: 0 | C30: 0 | E30: =$B$13 -> 1.1 | F30: =IFERROR(E30/E$25,0) -> 0.11528846 | G30: alleen retail/CB | H30: 1e druk | I30: =$B$7 -> 2000 | J30: =$B$10 -> 1.2 | K30: =I30*J30 -> 2400
A31: Transactiekosten | B31: =$B$4*$B$14 -> 0.2 | C31: =IFERROR(B31/B$25,0) -> 0.0109 | E31: 0 | F31: 0 | G31: alleen webshop | H31: 2e druk | I31: 0 | J31: 0 | K31: =I31*J31 -> 0
A32: Adspend | B32: =$B$17 -> 5 | C32: =IFERROR(B32/B$25,0) -> 0.2725 | E32: 0 | F32: 0 | G32: alleen webshop | H32: 3e druk | I32: 0 | J32: 0 | K32: =I32*J32 -> 0
A33: Vertaler | B33: =B23*$B$15 -> 0 | C33: =IFERROR(B33/B$25,0) -> 0 | E33: =E23*$B$15 -> 0 | F33: =IFERROR(E33/E$25,0) -> 0 | H33: 4e druk | I33: 0 | J33: 0 | K33: =I33*J33 -> 0
A34: Agent | B34: =B23*$B$16 -> 2.0183486 | C34: =IFERROR(B34/B$25,0) -> 0.11 | E34: =E23*$B$16 -> 2.0183486 | F34: =IFERROR(E34/E$25,0) -> 0.21153846 | H34: 5e druk | I34: 0 | J34: 0 | K34: =I34*J34 -> 0
A35: Overige kosten | B35: =B25*$B$18 -> 0 | C35: =$B$18 -> 0 | E35: =E25*$B$18 -> 0 | F35: =$B$18 -> 0
A36: Totaal kosten | B36: =SUM(B27:B35) -> 13.118349 | C36: =IFERROR(B36/B$25,0) -> 0.71495 | E36: =SUM(E27:E35) -> 4.3183486 | F36: =IFERROR(E36/E$25,0) -> 0.45259615 | H36: Totaal exemplaren | I36: =SUM(I30:I34) -> 2000 | K36: =SUM(K30:K34) -> 2400
H37: Gem. drukkosten /ex | J37: =IFERROR(K36/I36,0) -> 1.2
A38: Brutowinst | B38: =B25-B36 -> 5.2302752 | C38: =IFERROR(B38/B$25,0) -> 0.28505 | E38: =E25-E36 -> 5.2229358 | F38: =IFERROR(E38/E$25,0) -> 0.54740385
A39: Royalty | B39: =B23*$E$4 -> 0 | C39: =IFERROR(B39/B$25,0) -> 0 | E39: =E23*$E$4 -> 0 | F39: =IFERROR(E39/E$25,0) -> 0 | G39: % van prijs ex BTW
A40: Auteur winstdeling | B40: =(B38-B39)*$E$5 -> 2.6151376 | C40: =IFERROR(B40/B$25,0) -> 0.142525 | E40: =(E38-E39)*$E$5 -> 2.6114679 | F40: =IFERROR(E40/E$25,0) -> 0.27370192 | G40: % van winst na royalty
A41: Partner winstdeling | B41: =(B38-B39)*$E$6 -> 0 | C41: =IFERROR(B41/B$25,0) -> 0 | E41: =(E38-E39)*$E$6 -> 0 | F41: =IFERROR(E41/E$25,0) -> 0
...

Sheet Rechts verpest onze seks
A1: Rechts verpest onze seks | H1: REDACTIE & PRODUCTIE
H2: Post | I2: Begroot | J2: Gerealiseerd
A3: BASISGEGEVENS | D3: DEALSTRUCTUUR | H3: Freelance redactie | I3: 0
A4: Verkoopprijs incl BTW | B4: 17.5 | D4: Royalty % | E4: 0 | H4: Correctie | I4: 0
A5: BTW % | B5: 0.09 | D5: Auteur winstdeling % | E5: 0.45 | H5: Persklaarmaken | I5: 0
A6: Boekhandelskorting % | B6: 0.48 | D6: Partner winstdeling % | E6: 0 | H6: Vormgeving & omslag | I6: 0
A7: Oplage 1e druk | B7: 2000 | H7: DTP | I7: 0
H8: E-book productie | I8: 0
A9: KOSTEN PER EXEMPLAAR | H9: Audiobook productie | I9: 0
A10: Drukkosten /ex (1e druk) | B10: 1.2 | H10: Drukkosten 1e druk | I10: =$B$10*$B$7 -> 2400
A11: Drukkosten /ex (herdruk) | B11: 1.2 | H11: Overige productie | I11: 5200
A12: Fulfillment webshop /ex | B12: 4.7
A13: Distributie CB /ex | B13: 1.1 | H13: Subtotaal excl. drukkosten | I13: =SUM(I3:I9,I11) -> 5200 | J13: =SUM(J3:J9,J11) -> 0
A14: Transactiekosten % (webshop) | B14: 0.03 | H14: Totaal incl. drukkosten | I14: =SUM(I3:I11) -> 7600 | J14: =SUM(J3:J11) -> 0
A15: Vertaler % | B15: 0 | H15: Per exemplaar (excl. druk) | I15: =IFERROR(I13/$B$7,0) -> 2.6 | J15: =IFERROR(J13/$B$7,0) -> 0
A16: Agent % | B16: 0
A17: Adspend webshop /ex | B17: 0 | H17: PR & MARKETING
A18: Overige kosten % | B18: 0 | H18: Post | I18: Begroot | J18: Gerealiseerd
H19: PR activiteiten | I19: 0
A20: 1E DRUK | H20: Marketingmateriaal | I20: 0
B21: WEBSHOP | E21: RETAIL | H21: Evenementen | I21: 0
B22: Bedrag | C22: % | E22: Bedrag | F22: % | H22: Campagnes / advertenties | I22: 0
A23: Verkoopprijs ex BTW | B23: =$B$4/(1+$B$5) -> 16.055046 | E23: =$B$4/(1+$B$5) -> 16.055046 | H23: Overige marketing | I23: 0
A24: Boekhandelskorting | B24: 0 | C24: 0 | E24: =E23*$B$6 -> 7.706422 | F24: =$B$6 -> 0.48
A25: Netto omzet | B25: =B23 -> 16.055046 | E25: =E23-E24 -> 8.3486239 | H25: Totaal PR & Marketing | I25: =SUM(I19:I23) -> 0 | J25: =SUM(J19:J23) -> 0
A27: Drukkosten | B27: =$B$10 -> 1.2 | C27: =IFERROR(B27/B$25,0) -> 0.074742857 | E27: =$B$10 -> 1.2 | F27: =IFERROR(E27/E$25,0) -> 0.14373626
A28: Redactie & productie /ex | B28: =IFERROR(I15/$B$7,0) -> 0.0013 | C28: =IFERROR(B28/B$25,0) -> 8.0971429e-05 | E28: =IFERROR(I15/$B$7,0) -> 0.0013 | F28: =IFERROR(E28/E$25,0) -> 0.00015571429 | H28: DRUKRUNS
A29: Fulfillment / B-Logic | B29: =$B$12 -> 4.7 | C29: =IFERROR(B29/B$25,0) -> 0.29274286 | E29: 0 | F29: 0 | G29: alleen webshop | H29: Run | I29: Aantal | J29: Kosten /ex | K29: Totaal
A30: Distributie CB | B30: 0 | C30: 0 | E30: =$B$13 -> 1.1 | F30: =IFERROR(E30/E$25,0) -> 0.13175824 | G30: alleen retail/CB | H30: 1e druk | I30: =$B$7 -> 2000 | J30: =$B$10 -> 1.2 | K30: =I30*J30 -> 2400
A31: Transactiekosten | B31: =$B$4*$B$14 -> 0.525 | C31: =IFERROR(B31/B$25,0) -> 0.0327 | E31: 0 | F31: 0 | G31: alleen webshop | H31: 2e druk | I31: 0 | J31: 0 | K31: =I31*J31 -> 0
A32: Adspend | B32: =$B$17 -> 0 | C32: =IFERROR(B32/B$25,0) -> 0 | E32: 0 | F32: 0 | G32: alleen webshop | H32: 3e druk | I32: 0 | J32: 0 | K32: =I32*J32 -> 0
A33: Vertaler | B33: =B23*$B$15 -> 0 | C33: =IFERROR(B33/B$25,0) -> 0 | E33: =E23*$B$15 -> 0 | F33: =IFERROR(E33/E$25,0) -> 0 | H33: 4e druk | I33: 0 | J33: 0 | K33: =I33*J33 -> 0
A34: Agent | B34: =B23*$B$16 -> 0 | C34: =IFERROR(B34/B$25,0) -> 0 | E34: =E23*$B$16 -> 0 | F34: =IFERROR(E34/E$25,0) -> 0 | H34: 5e druk | I34: 0 | J34: 0 | K34: =I34*J34 -> 0
A35: Overige kosten | B35: =B25*$B$18 -> 0 | C35: =$B$18 -> 0 | E35: =E25*$B$18 -> 0 | F35: =$B$18 -> 0
A36: Totaal kosten | B36: =SUM(B27:B35) -> 6.4263 | C36: =IFERROR(B36/B$25,0) -> 0.40026669 | E36: =SUM(E27:E35) -> 2.3013 | F36: =IFERROR(E36/E$25,0) -> 0.27565022 | H36: Totaal exemplaren | I36: =SUM(I30:I34) -> 2000 | K36: =SUM(K30:K34) -> 2400
H37: Gem. drukkosten /ex | J37: =IFERROR(K36/I36,0) -> 1.2
A38: Brutowinst | B38: =B25-B36 -> 9.6287459 | C38: =IFERROR(B38/B$25,0) -> 0.59973331 | E38: =E25-E36 -> 6.0473239 | F38: =IFERROR(E38/E$25,0) -> 0.72434978
A39: Royalty | B39: =B23*$E$4 -> 0 | C39: =IFERROR(B39/B$25,0) -> 0 | E39: =E23*$E$4 -> 0 | F39: =IFERROR(E39/E$25,0) -> 0 | G39: % van prijs ex BTW
A40: Auteur winstdeling | B40: =(B38-B39)*$E$5 -> 4.3329356 | C40: =IFERROR(B40/B$25,0) -> 0.26987999 | E40: =(E38-E39)*$E$5 -> 2.7212957 | F40: =IFERROR(E40/E$25,0) -> 0.3259574 | G40: % van winst na royalty
A41: Partner winstdeling | B41: =(B38-B39)*$E$6 -> 0 | C41: =IFERROR(B41/B$25,0) -> 0 | E41: =(E38-E39)*$E$6 -> 0 | F41: =IFERROR(E41/E$25,0) -> 0
...

Sheet 7 regels van vertrouwen
A1: 7 regels van vertrouwen | H1: REDACTIE & PRODUCTIE
H2: Post | I2: Begroot | J2: Gerealiseerd
A3: BASISGEGEVENS | D3: DEALSTRUCTUUR | H3: Freelance redactie | I3: 0
A4: Verkoopprijs incl BTW | B4: 0 | D4: Royalty % | E4: 0 | H4: Correctie | I4: 0
A5: BTW % | B5: 0.09 | D5: Auteur winstdeling % | E5: 0 | H5: Persklaarmaken | I5: 0
A6: Boekhandelskorting % | B6: 0.48 | D6: Partner winstdeling % | E6: 0 | H6: Vormgeving & omslag | I6: 0
A7: Oplage 1e druk | B7: 0 | H7: DTP | I7: 0
H8: E-book productie | I8: 0
A9: KOSTEN PER EXEMPLAAR | H9: Audiobook productie | I9: 0
A10: Drukkosten /ex (1e druk) | B10: 0 | H10: Drukkosten 1e druk | I10: =$B$10*$B$7 -> 0
A11: Drukkosten /ex (herdruk) | B11: 0 | H11: Overige productie | I11: 0
A12: Fulfillment webshop /ex | B12: 4.7
A13: Distributie CB /ex | B13: 1.1 | H13: Subtotaal excl. drukkosten | I13: =SUM(I3:I9,I11) -> 0 | J13: =SUM(J3:J9,J11) -> 0
A14: Transactiekosten % (webshop) | B14: 0.01 | H14: Totaal incl. drukkosten | I14: =SUM(I3:I11) -> 0 | J14: =SUM(J3:J11) -> 0
A15: Vertaler % | B15: 0 | H15: Per exemplaar (excl. druk) | I15: =IFERROR(I13/$B$7,0) -> 0 | J15: =IFERROR(J13/$B$7,0) -> 0
A16: Agent % | B16: 0
A17: Adspend webshop /ex | B17: 0 | H17: PR & MARKETING
A18: Overige kosten % | B18: 0 | H18: Post | I18: Begroot | J18: Gerealiseerd
H19: PR activiteiten | I19: 0
A20: 1E DRUK | H20: Marketingmateriaal | I20: 0
B21: WEBSHOP | E21: RETAIL | H21: Evenementen | I21: 0
B22: Bedrag | C22: % | E22: Bedrag | F22: % | H22: Campagnes / advertenties | I22: 0
A23: Verkoopprijs ex BTW | B23: =$B$4/(1+$B$5) -> 0 | E23: =$B$4/(1+$B$5) -> 0 | H23: Overige marketing | I23: 0
A24: Boekhandelskorting | B24: 0 | C24: 0 | E24: =E23*$B$6 -> 0 | F24: =$B$6 -> 0.48
A25: Netto omzet | B25: =B23 -> 0 | E25: =E23-E24 -> 0 | H25: Totaal PR & Marketing | I25: =SUM(I19:I23) -> 0 | J25: =SUM(J19:J23) -> 0
A27: Drukkosten | B27: =$B$10 -> 0 | C27: =IFERROR(B27/B$25,0) -> 0 | E27: =$B$10 -> 0 | F27: =IFERROR(E27/E$25,0) -> 0
A28: Redactie & productie /ex | B28: =IFERROR(I15/$B$7,0) -> 0 | C28: =IFERROR(B28/B$25,0) -> 0 | E28: =IFERROR(I15/$B$7,0) -> 0 | F28: =IFERROR(E28/E$25,0) -> 0 | H28: DRUKRUNS
A29: Fulfillment / B-Logic | B29: =$B$12 -> 4.7 | C29: =IFERROR(B29/B$25,0) -> 0 | E29: 0 | F29: 0 | G29: alleen webshop | H29: Run | I29: Aantal | J29: Kosten /ex | K29: Totaal
A30: Distributie CB | B30: 0 | C30: 0 | E30: =$B$13 -> 1.1 | F30: =IFERROR(E30/E$25,0) -> 0 | G30: alleen retail/CB | H30: 1e druk | I30: =$B$7 -> 0 | J30: =$B$10 -> 0 | K30: =I30*J30 -> 0
A31: Transactiekosten | B31: =$B$4*$B$14 -> 0 | C31: =IFERROR(B31/B$25,0) -> 0 | E31: 0 | F31: 0 | G31: alleen webshop | H31: 2e druk | I31: 0 | J31: 0 | K31: =I31*J31 -> 0
A32: Adspend | B32: =$B$17 -> 0 | C32: =IFERROR(B32/B$25,0) -> 0 | E32: 0 | F32: 0 | G32: alleen webshop | H32: 3e druk | I32: 0 | J32: 0 | K32: =I32*J32 -> 0
A33: Vertaler | B33: =B23*$B$15 -> 0 | C33: =IFERROR(B33/B$25,0) -> 0 | E33: =E23*$B$15 -> 0 | F33: =IFERROR(E33/E$25,0) -> 0 | H33: 4e druk | I33: 0 | J33: 0 | K33: =I33*J33 -> 0
A34: Agent | B34: =B23*$B$16 -> 0 | C34: =IFERROR(B34/B$25,0) -> 0 | E34: =E23*$B$16 -> 0 | F34: =IFERROR(E34/E$25,0) -> 0 | H34: 5e druk | I34: 0 | J34: 0 | K34: =I34*J34 -> 0
A35: Overige kosten | B35: =B25*$B$18 -> 0 | C35: =$B$18 -> 0 | E35: =E25*$B$18 -> 0 | F35: =$B$18 -> 0
A36: Totaal kosten | B36: =SUM(B27:B35) -> 4.7 | C36: =IFERROR(B36/B$25,0) -> 0 | E36: =SUM(E27:E35) -> 1.1 | F36: =IFERROR(E36/E$25,0) -> 0 | H36: Totaal exemplaren | I36: =SUM(I30:I34) -> 0 | K36: =SUM(K30:K34) -> 0
H37: Gem. drukkosten /ex | J37: =IFERROR(K36/I36,0) -> 0
A38: Brutowinst | B38: =B25-B36 -> -4.7 | C38: =IFERROR(B38/B$25,0) -> 0 | E38: =E25-E36 -> -1.1 | F38: =IFERROR(E38/E$25,0) -> 0
A39: Royalty | B39: =B23*$E$4 -> 0 | C39: =IFERROR(B39/B$25,0) -> 0 | E39: =E23*$E$4 -> 0 | F39: =IFERROR(E39/E$25,0) -> 0 | G39: % van prijs ex BTW
A40: Auteur winstdeling | B40: =(B38-B39)*$E$5 -> 0 | C40: =IFERROR(B40/B$25,0) -> 0 | E40: =(E38-E39)*$E$5 -> 0 | F40: =IFERROR(E40/E$25,0) -> 0 | G40: % van winst na royalty
A41: Partner winstdeling | B41: =(B38-B39)*$E$6 -> 0 | C41: =IFERROR(B41/B$25,0) -> 0 | E41: =(E38-E39)*$E$6 -> 0 | F41: =IFERROR(E41/E$25,0) -> 0
...

Sheet Nieuwe titel
A1: Nieuwe titel | H1: REDACTIE & PRODUCTIE
H2: Post | I2: Begroot | J2: Gerealiseerd
A3: BASISGEGEVENS | D3: DEALSTRUCTUUR | H3: Freelance redactie | I3: 0
A4: Verkoopprijs incl BTW | B4: 0 | D4: Royalty % | E4: 0 | H4: Correctie | I4: 0
A5: BTW % | B5: 0.09 | D5: Auteur winstdeling % | E5: 0 | H5: Persklaarmaken | I5: 0
A6: Boekhandelskorting % | B6: 0.48 | D6: Partner winstdeling % | E6: 0 | H6: Vormgeving & omslag | I6: 0
A7: Oplage 1e druk | B7: 0 | H7: DTP | I7: 0
H8: E-book productie | I8: 0
A9: KOSTEN PER EXEMPLAAR | H9: Audiobook productie | I9: 0
A10: Drukkosten /ex (1e druk) | B10: 0 | H10: Drukkosten 1e druk | I10: =$B$10*$B$7 -> 0
A11: Drukkosten /ex (herdruk) | B11: 0 | H11: Overige productie | I11: 0
A12: Fulfillment webshop /ex | B12: 4.7
A13: Distributie CB /ex | B13: 1.1 | H13: Subtotaal excl. drukkosten | I13: =SUM(I3:I9,I11) -> 0 | J13: =SUM(J3:J9,J11) -> 0
A14: Transactiekosten % (webshop) | B14: 0.01 | H14: Totaal incl. drukkosten | I14: =SUM(I3:I11) -> 0 | J14: =SUM(J3:J11) -> 0
A15: Vertaler % | B15: 0 | H15: Per exemplaar (excl. druk) | I15: =IFERROR(I13/$B$7,0) -> 0 | J15: =IFERROR(J13/$B$7,0) -> 0
A16: Agent % | B16: 0
A17: Adspend webshop /ex | B17: 0 | H17: PR & MARKETING
A18: Overige kosten % | B18: 0 | H18: Post | I18: Begroot | J18: Gerealiseerd
H19: PR activiteiten | I19: 0
A20: 1E DRUK | H20: Marketingmateriaal | I20: 0
B21: WEBSHOP | E21: RETAIL | H21: Evenementen | I21: 0
B22: Bedrag | C22: % | E22: Bedrag | F22: % | H22: Campagnes / advertenties | I22: 0
A23: Verkoopprijs ex BTW | B23: =$B$4/(1+$B$5) -> 0 | E23: =$B$4/(1+$B$5) -> 0 | H23: Overige marketing | I23: 0
A24: Boekhandelskorting | B24: 0 | C24: 0 | E24: =E23*$B$6 -> 0 | F24: =$B$6 -> 0.48
A25: Netto omzet | B25: =B23 -> 0 | E25: =E23-E24 -> 0 | H25: Totaal PR & Marketing | I25: =SUM(I19:I23) -> 0 | J25: =SUM(J19:J23) -> 0
A27: Drukkosten | B27: =$B$10 -> 0 | C27: =IFERROR(B27/B$25,0) -> 0 | E27: =$B$10 -> 0 | F27: =IFERROR(E27/E$25,0) -> 0
A28: Redactie & productie /ex | B28: =IFERROR(I15/$B$7,0) -> 0 | C28: =IFERROR(B28/B$25,0) -> 0 | E28: =IFERROR(I15/$B$7,0) -> 0 | F28: =IFERROR(E28/E$25,0) -> 0 | H28: DRUKRUNS
A29: Fulfillment / B-Logic | B29: =$B$12 -> 4.7 | C29: =IFERROR(B29/B$25,0) -> 0 | E29: 0 | F29: 0 | G29: alleen webshop | H29: Run | I29: Aantal | J29: Kosten /ex | K29: Totaal
A30: Distributie CB | B30: 0 | C30: 0 | E30: =$B$13 -> 1.1 | F30: =IFERROR(E30/E$25,0) -> 0 | G30: alleen retail/CB | H30: 1e druk | I30: =$B$7 -> 0 | J30: =$B$10 -> 0 | K30: =I30*J30 -> 0
A31: Transactiekosten | B31: =$B$4*$B$14 -> 0 | C31: =IFERROR(B31/B$25,0) -> 0 | E31: 0 | F31: 0 | G31: alleen webshop | H31: 2e druk | I31: 0 | J31: 0 | K31: =I31*J31 -> 0
A32: Adspend | B32: =$B$17 -> 0 | C32: =IFERROR(B32/B$25,0) -> 0 | E32: 0 | F32: 0 | G32: alleen webshop | H32: 3e druk | I32: 0 | J32: 0 | K32: =I32*J32 -> 0
A33: Vertaler | B33: =B23*$B$15 -> 0 | C33: =IFERROR(B33/B$25,0) -> 0 | E33: =E23*$B$15 -> 0 | F33: =IFERROR(E33/E$25,0) -> 0 | H33: 4e druk | I33: 0 | J33: 0 | K33: =I33*J33 -> 0
A34: Agent | B34: =B23*$B$16 -> 0 | C34: =IFERROR(B34/B$25,0) -> 0 | E34: =E23*$B$16 -> 0 | F34: =IFERROR(E34/E$25,0) -> 0 | H34: 5e druk | I34: 0 | J34: 0 | K34: =I34*J34 -> 0
A35: Overige kosten | B35: =B25*$B$18 -> 0 | C35: =$B$18 -> 0 | E35: =E25*$B$18 -> 0 | F35: =$B$18 -> 0
A36: Totaal kosten | B36: =SUM(B27:B35) -> 4.7 | C36: =IFERROR(B36/B$25,0) -> 0 | E36: =SUM(E27:E35) -> 1.1 | F36: =IFERROR(E36/E$25,0) -> 0 | H36: Totaal exemplaren | I36: =SUM(I30:I34) -> 0 | K36: =SUM(K30:K34) -> 0
H37: Gem. drukkosten /ex | J37: =IFERROR(K36/I36,0) -> 0
A38: Brutowinst | B38: =B25-B36 -> -4.7 | C38: =IFERROR(B38/B$25,0) -> 0 | E38: =E25-E36 -> -1.1 | F38: =IFERROR(E38/E$25,0) -> 0
A39: Royalty | B39: =B23*$E$4 -> 0 | C39: =IFERROR(B39/B$25,0) -> 0 | E39: =E23*$E$4 -> 0 | F39: =IFERROR(E39/E$25,0) -> 0 | G39: % van prijs ex BTW
A40: Auteur winstdeling | B40: =(B38-B39)*$E$5 -> 0 | C40: =IFERROR(B40/B$25,0) -> 0 | E40: =(E38-E39)*$E$5 -> 0 | F40: =IFERROR(E40/E$25,0) -> 0 | G40: % van winst na royalty
A41: Partner winstdeling | B41: =(B38-B39)*$E$6 -> 0 | C41: =IFERROR(B41/B$25,0) -> 0 | E41: =(E38-E39)*$E$6 -> 0 | F41: =IFERROR(E41/E$25,0) -> 0
...
